Traceback (most recent call last):
  File "/Users/inertialframe/opt/anaconda3/envs/qe-mini-example/lib/python3.8/site-packages/jupyter_cache/executors/utils.py", line 51, in single_nb_execution
    executenb(
  File "/Users/inertialframe/opt/anaconda3/envs/qe-mini-example/lib/python3.8/site-packages/nbclient/client.py", line 1117, in execute
    return NotebookClient(nb=nb, resources=resources, km=km, **kwargs).execute()
  File "/Users/inertialframe/opt/anaconda3/envs/qe-mini-example/lib/python3.8/site-packages/nbclient/util.py", line 78, in wrapped
    return just_run(coro(*args, **kwargs))
  File "/Users/inertialframe/opt/anaconda3/envs/qe-mini-example/lib/python3.8/site-packages/nbclient/util.py", line 57, in just_run
    return loop.run_until_complete(coro)
  File "/Users/inertialframe/opt/anaconda3/envs/qe-mini-example/lib/python3.8/asyncio/base_events.py", line 616, in run_until_complete
    return future.result()
  File "/Users/inertialframe/opt/anaconda3/envs/qe-mini-example/lib/python3.8/site-packages/nbclient/client.py", line 558, in async_execute
    await self.async_execute_cell(
  File "/Users/inertialframe/opt/anaconda3/envs/qe-mini-example/lib/python3.8/site-packages/nbclient/client.py", line 862, in async_execute_cell
    self._check_raise_for_error(cell, exec_reply)
  File "/Users/inertialframe/opt/anaconda3/envs/qe-mini-example/lib/python3.8/site-packages/nbclient/client.py", line 765, in _check_raise_for_error
    raise CellExecutionError.from_cell_and_msg(cell, exec_reply_content)
nbclient.exceptions.CellExecutionError: An error occurred while executing the following cell:
------------------
B.dcm(A)
------------------

[0;31m---------------------------------------------------------------------------[0m
[0;31mValueError[0m                                Traceback (most recent call last)
[0;32m/var/folders/nv/1xnwf7gx3kx0c_dlh9wxbqkc0000gn/T/ipykernel_73448/3951029059.py[0m in [0;36m<module>[0;34m[0m
[0;32m----> 1[0;31m [0mB[0m[0;34m.[0m[0mdcm[0m[0;34m([0m[0mA[0m[0;34m)[0m[0;34m[0m[0;34m[0m[0m
[0m
[0;32m~/opt/anaconda3/envs/qe-mini-example/lib/python3.8/site-packages/sympy/physics/vector/frame.py[0m in [0;36mdcm[0;34m(self, otherframe)[0m
[1;32m    519[0m         [0;32mif[0m [0motherframe[0m [0;32min[0m [0mself[0m[0;34m.[0m[0m_dcm_cache[0m[0;34m:[0m[0;34m[0m[0;34m[0m[0m
[1;32m    520[0m             [0;32mreturn[0m [0mself[0m[0;34m.[0m[0m_dcm_cache[0m[0;34m[[0m[0motherframe[0m[0;34m][0m[0;34m[0m[0;34m[0m[0m
[0;32m--> 521[0;31m         [0mflist[0m [0;34m=[0m [0mself[0m[0;34m.[0m[0m_dict_list[0m[0;34m([0m[0motherframe[0m[0;34m,[0m [0;36m0[0m[0;34m)[0m[0;34m[0m[0;34m[0m[0m
[0m[1;32m    522[0m         [0moutdcm[0m [0;34m=[0m [0meye[0m[0;34m([0m[0;36m3[0m[0;34m)[0m[0;34m[0m[0;34m[0m[0m
[1;32m    523[0m         [0;32mfor[0m [0mi[0m [0;32min[0m [0mrange[0m[0;34m([0m[0mlen[0m[0;34m([0m[0mflist[0m[0;34m)[0m [0;34m-[0m [0;36m1[0m[0;34m)[0m[0;34m:[0m[0;34m[0m[0;34m[0m[0m

[0;32m~/opt/anaconda3/envs/qe-mini-example/lib/python3.8/site-packages/sympy/physics/vector/frame.py[0m in [0;36m_dict_list[0;34m(self, other, num)[0m
[1;32m    320[0m [0;34m[0m[0m
[1;32m    321[0m         [0mmsg[0m [0;34m=[0m [0;34m'No connecting {} path found between {} and {}.'[0m[0;34m[0m[0;34m[0m[0m
[0;32m--> 322[0;31m         [0;32mraise[0m [0mValueError[0m[0;34m([0m[0mmsg[0m[0;34m.[0m[0mformat[0m[0;34m([0m[0mconnect_type[0m[0;34m[[0m[0mnum[0m[0;34m][0m[0;34m,[0m [0mself[0m[0;34m.[0m[0mname[0m[0;34m,[0m [0mother[0m[0;34m.[0m[0mname[0m[0;34m)[0m[0;34m)[0m[0;34m[0m[0;34m[0m[0m
[0m[1;32m    323[0m [0;34m[0m[0m
[1;32m    324[0m     [0;32mdef[0m [0m_w_diff_dcm[0m[0;34m([0m[0mself[0m[0;34m,[0m [0motherframe[0m[0;34m)[0m[0;34m:[0m[0;34m[0m[0;34m[0m[0m

[0;31mValueError[0m: No connecting orientation path found between B and A.
ValueError: No connecting orientation path found between B and A.

